2025-05-13 16:02:22,373 | ERROR | app.services.messaging.client | (client.py:192) | Failed to send image: {"error":{"message":"(#100) Param image['link'] is not a valid URI.","type":"OAuthException","code":100,"fbtrace_id":"AgcWdEwUQveomQfoo_MwLZo"}}
Stack:
  File "<string>", line 1, in <module>
  File "/home/codespace/.python/current/lib/python3.12/multiprocessing/spawn.py", line 122, in spawn_main
    exitcode = _main(fd, parent_sentinel)
  File "/home/codespace/.python/current/lib/python3.12/multiprocessing/spawn.py", line 135, in _main
    return self._bootstrap(parent_sentinel)
  File "/home/codespace/.python/current/lib/python3.12/multiprocessing/process.py", line 314, in _bootstrap
    self.run()
  File "/home/codespace/.python/current/lib/python3.12/multiprocessing/process.py", line 108, in run
    self._target(*self._args, **self._kwargs)
  File "/workspaces/elevate2ai/.venv/lib/python3.12/site-packages/uvicorn/_subprocess.py", line 80, in subprocess_started
    target(sockets=sockets)
  File "/workspaces/elevate2ai/.venv/lib/python3.12/site-packages/uvicorn/server.py", line 66, in run
    return asyncio.run(self.serve(sockets=sockets))
  File "/home/codespace/.python/current/lib/python3.12/asyncio/runners.py", line 194, in run
    return runner.run(main)
  File "/home/codespace/.python/current/lib/python3.12/asyncio/runners.py", line 118, in run
    return self._loop.run_until_complete(task)
  File "/home/codespace/.python/current/lib/python3.12/asyncio/base_events.py", line 671, in run_until_complete
    self.run_forever()
  File "/home/codespace/.python/current/lib/python3.12/asyncio/base_events.py", line 638, in run_forever
    self._run_once()
  File "/home/codespace/.python/current/lib/python3.12/asyncio/base_events.py", line 1971, in _run_once
    handle._run()
  File "/home/codespace/.python/current/lib/python3.12/asyncio/events.py", line 84, in _run
    self._context.run(self._callback, *self._args)
  File "/workspaces/elevate2ai/app/services/workflow/manager.py", line 104, in _message_processor
    await handler(client_id, message_text.strip().lower())
  File "/workspaces/elevate2ai/app/services/workflow/handlers/scheduling.py", line 46, in handle
    await self.send_confirmation_summary(client_id, context)
  File "/workspaces/elevate2ai/app/services/workflow/handlers/scheduling.py", line 96, in send_confirmation_summary
    await self.client.send_media(
  File "/workspaces/elevate2ai/app/services/messaging/client.py", line 192, in send_media
    self.logger.error(
  File "/home/codespace/.python/current/lib/python3.12/logging/__init__.py", line 1568, in error
    self._log(ERROR, msg, args, **kwargs)
  File "/home/codespace/.python/current/lib/python3.12/logging/__init__.py", line 1684, in _log
    self.handle(record)
  File "/home/codespace/.python/current/lib/python3.12/logging/__init__.py", line 1700, in handle
    self.callHandlers(record)
  File "/home/codespace/.python/current/lib/python3.12/logging/__init__.py", line 1762, in callHandlers
    hdlr.handle(record)
  File "/home/codespace/.python/current/lib/python3.12/logging/__init__.py", line 1028, in handle
    self.emit(record)

