ERROR | app.api.webhook | (logging.py:121) | Error processing webhook data
Traceback (most recent call last):
  File "/workspaces/elevate2ai/app/api/webhook.py", line 77, in handle_message
    message_text = await workflow_manager.retrieve_text(media_id)
                         ^^^^^^^^^^^^^^^^^^^^^^^^^^^^^^
AttributeError: 'WorkflowManager' object has no attribute 'retrieve_text'

Stack:
  File "<string>", line 1, in <module>
  File "/home/codespace/.python/current/lib/python3.12/multiprocessing/spawn.py", line 122, in spawn_main
    exitcode = _main(fd, parent_sentinel)
  File "/home/codespace/.python/current/lib/python3.12/multiprocessing/spawn.py", line 135, in _main
    return self._bootstrap(parent_sentinel)
  File "/home/codespace/.python/current/lib/python3.12/multiprocessing/process.py", line 314, in _bootstrap
    self.run()
  File "/home/codespace/.python/current/lib/python3.12/multiprocessing/process.py", line 108, in run
    self._target(*self._args, **self._kwargs)
  File "/workspaces/elevate2ai/.venv/lib/python3.12/site-packages/uvicorn/_subprocess.py", line 80, in subprocess_started
    target(sockets=sockets)
  File "/workspaces/elevate2ai/.venv/lib/python3.12/site-packages/uvicorn/server.py", line 66, in run
    return asyncio.run(self.serve(sockets=sockets))
  File "/home/codespace/.python/current/lib/python3.12/asyncio/runners.py", line 194, in run
    return runner.run(main)
  File "/home/codespace/.python/current/lib/python3.12/asyncio/runners.py", line 118, in run
    return self._loop.run_until_complete(task)
  File "/home/codespace/.python/current/lib/python3.12/asyncio/base_events.py", line 671, in run_until_complete
    self.run_forever()
  File "/home/codespace/.python/current/lib/python3.12/asyncio/base_events.py", line 638, in run_forever
    self._run_once()
  File "/home/codespace/.python/current/lib/python3.12/asyncio/base_events.py", line 1971, in _run_once
    handle._run()
  File "/home/codespace/.python/current/lib/python3.12/asyncio/events.py", line 84, in _run
    self._context.run(self._callback, *self._args)
  File "/workspaces/elevate2ai/.venv/lib/python3.12/site-packages/uvicorn/protocols/http/h11_impl.py", line 403, in run_asgi
    result = await app(  # type: ignore[func-returns-value]
  File "/workspaces/elevate2ai/.venv/lib/python3.12/site-packages/uvicorn/middleware/proxy_headers.py", line 60, in __call__
    return await self.app(scope, receive, send)
  File "/workspaces/elevate2ai/.venv/lib/python3.12/site-packages/fastapi/applications.py", line 1054, in __call__
    await super().__call__(scope, receive, send)
  File "/workspaces/elevate2ai/.venv/lib/python3.12/site-packages/starlette/applications.py", line 112, in __call__
    await self.middleware_stack(scope, receive, send)
  File "/workspaces/elevate2ai/.venv/lib/python3.12/site-packages/starlette/middleware/errors.py", line 165, in __call__
    await self.app(scope, receive, _send)
  File "/workspaces/elevate2ai/app/middleware.py", line 38, in __call__
    return await self.app(scope, receive, send)
  File "/workspaces/elevate2ai/.venv/lib/python3.12/site-packages/starlette/middleware/cors.py", line 85, in __call__
    await self.app(scope, receive, send)
  File "/workspaces/elevate2ai/.venv/lib/python3.12/site-packages/starlette/middleware/exceptions.py", line 62, in __call__
    await wrap_app_handling_exceptions(self.app, conn)(scope, receive, send)
  File "/workspaces/elevate2ai/.venv/lib/python3.12/site-packages/starlette/_exception_handler.py", line 42, in wrapped_app
    await app(scope, receive, sender)
  File "/workspaces/elevate2ai/.venv/lib/python3.12/site-packages/starlette/routing.py", line 714, in __call__
    await self.middleware_stack(scope, receive, send)
  File "/workspaces/elevate2ai/.venv/lib/python3.12/site-packages/starlette/routing.py", line 734, in app
    await route.handle(scope, receive, send)
  File "/workspaces/elevate2ai/.venv/lib/python3.12/site-packages/starlette/routing.py", line 288, in handle
    await self.app(scope, receive, send)
  File "/workspaces/elevate2ai/.venv/lib/python3.12/site-packages/starlette/routing.py", line 76, in app
    await wrap_app_handling_exceptions(app, request)(scope, receive, send)
  File "/workspaces/elevate2ai/.venv/lib/python3.12/site-packages/starlette/_exception_handler.py", line 42, in wrapped_app
    await app(scope, receive, sender)
  File "/workspaces/elevate2ai/.venv/lib/python3.12/site-packages/starlette/routing.py", line 73, in app
    response = await f(request)
  File "/workspaces/elevate2ai/.venv/lib/python3.12/site-packages/fastapi/routing.py", line 301, in app
    raw_response = await run_endpoint_function(
  File "/workspaces/elevate2ai/.venv/lib/python3.12/site-packages/fastapi/routing.py", line 212, in run_endpoint_function
    return await dependant.call(**values)
  File "/workspaces/elevate2ai/app/main.py", line 97, in webhook_handler
    return await handle_message(data)
  File "/workspaces/elevate2ai/app/api/webhook.py", line 120, in handle_message
    log_exception(logger, error_msg, e)
  File "/workspaces/elevate2ai/app/services/common/logging.py", line 121, in log_exception
    logger.error(f"{message}\n{tb_text}")
  File "/home/codespace/.python/current/lib/python3.12/logging/__init__.py", line 1568, in error
    self._log(ERROR, msg, args, **kwargs)
  File "/home/codespace/.python/current/lib/python3.12/logging/__init__.py", line 1684, in _log
    self.handle(record)
  File "/home/codespace/.python/current/lib/python3.12/logging/__init__.py", line 1700, in handle
    self.callHandlers(record)
  File "/home/codespace/.python/current/lib/python3.12/logging/__init__.py", line 1762, in callHandlers
    hdlr.handle(record)
  File "/home/codespace/.python/current/lib/python3.12/logging/__init__.py", line 1028, in handle
    self.emit(record)

